Workbook
Name AsOfDate: 'Read me'!$B$7

Sheet Read me
A1: ZAV-HZN Cutover Plan v0.3
A2: Fictitious test data – Copilot for Frontier Consultancy scenario testing
A4: Purpose | B4: Draft cutover runbook (v0.3) for the Zava Horizon go-live: D365 Finance + Supply Chain (F&O) and D365 Sales / Customer Service (CE). Cutover weekend Fri 26 Feb – Sun 28 Feb 2027, go-live Mon 1 Mar 2027. Use for testing runbook review, dependency checking, critical path, Go/No-Go preparation and owner briefings.
A5: Programme | B5: Zava Horizon (ZAV-HZN) – Zava LLC, delivered by Frontier Consulting
A6: Data as of | B6: Monday 19 Oct 2026 (Dubai, UTC+4)
A7: As-of date (used in formulas) | B7: 46314
A8: Currency | B8: AED
A9: Prepared by | B9: Priya Nair, Project Manager (Frontier Consulting) – scenario owner Lorette Roos
A11: Sheet | B11: Contents
A12: Runbook | B12: 112 tasks across Pre-cutover (T-14 to T-1), Freeze, Data migration, Technical, Business validation, three Go/No-Go gates, Go-live and Hypercare day 1. Planned end = planned start + duration.
A13: Phase summary | B13: Task counts, earliest start, latest finish and total hours by phase (formulas).
A15: Version | B15: v0.3 DRAFT – for review at design authority; not yet baselined. Times are Gulf Standard Time (UTC+4).
A16: Go/No-Go gates | B16: Gate 1 Fri 26 Feb (start data migration) | Gate 2 Sat 27 Feb (start business validation) | Gate 3 Sun 28 Feb 16:00 (final Go/No-Go)
A18: Important | B18: Fictitious test data – Copilot for Frontier Consultancy scenario testing. All companies, people and figures are fictitious and must not be used for real decisions.

Sheet Runbook
A1: ZAV-HZN Cutover Plan v0.3 (DRAFT) | Fictitious test data – Copilot for Frontier Consultancy scenario testing
A2: Task ID | B2: Phase | C2: Task | D2: Planned start | E2: Planned end | F2: Duration (h) | G2: Predecessor IDs | H2: Owner | I2: Team | J2: Status | K2: Evidence required | L2: Comments
A3: CUT-001 | B3: Pre-cutover (T-14 to T-1) | C3: Cutover plan v1.0 baselined and circulated | D3: 46430.375 | E3: =D3+F3/24 -> 46430.542 | F3: 4 | H3: Priya Nair | I3: PMO | J3: In planning | K3: Signed cutover plan | L3: T-14
A4: CUT-002 | B4: Pre-cutover (T-14 to T-1) | C4: Confirm cutover roles, rota and contact list | D4: 46430.542 | E4: =D4+F4/24 -> 46430.708 | F4: 4 | G4: CUT-001 | H4: Priya Nair | I4: PMO | J4: In planning | K4: Contact list in Teams channel
A5: CUT-003 | B5: Pre-cutover (T-14 to T-1) | C5: Production environment deployed with final release package | D5: 46430.417 | E5: =D5+F5/24 -> 46430.75 | F5: 8 | H5: Arjun Mehta | I5: Frontier – Integration | J5: In planning | K5: LCS/PPAC deployment log
A6: CUT-004 | B6: Pre-cutover (T-14 to T-1) | C6: CE production solutions imported (managed) | D6: 46430.75 | E6: =D6+F6/24 -> 46430.917 | F6: 4 | G6: CUT-003 | H6: Arjun Mehta | I6: Frontier – CE | J6: In planning | K6: Solution import history
A7: CUT-005 | B7: Pre-cutover (T-14 to T-1) | C7: Security roles and user access provisioned in F&O and CE | D7: 46433.375 | E7: =D7+F7/24 -> 46434.042 | F7: 16 | G7: CUT-003 | H7: Ravi Kumar | I7: Zava IT | J7: Not started | K7: User access report
A8: CUT-006 | B8: Pre-cutover (T-14 to T-1) | C8: Final mock cutover (Mock 3) results signed off | D8: 46433.375 | E8: =D8+F8/24 -> 46433.708 | F8: 8 | H8: Noura Al Hashimi | I8: Frontier – Data | J8: Not started | K8: Mock 3 reconciliation pack | L8: Mock 3 ran 6–7 Feb
A9: CUT-007 | B9: Pre-cutover (T-14 to T-1) | C9: Static master data loaded to production (COA, dimensions, posting profiles) | D9: 46433.542 | E9: =D9+F9/24 -> 46434.042 | F9: 12 | G9: CUT-003, CUT-006 | H9: Noura Al Hashimi | I9: Frontier – Data | J9: Not started | K9: Load log and record counts
A10: CUT-008 | B10: Pre-cutover (T-14 to T-1) | C10: Vendor master (de-duplicated) loaded to production | D10: 46434.042 | E10: =D10+F10/24 -> 46434.375 | F10: 8 | G10: CUT-007 | H10: Noura Al Hashimi | I10: Frontier – Data | J10: Not started | K10: Dedup report and load log
A11: CUT-009 | B11: Pre-cutover (T-14 to T-1) | C11: Customer master loaded to production | D11: 46434.375 | E11: =D11+F11/24 -> 46434.708 | F11: 8 | G11: CUT-008 | H11: Noura Al Hashimi | I11: Frontier – Data | J11: Not started | K11: Load log
A12: CUT-010 | B12: Pre-cutover (T-14 to T-1) | C12: Vendor and customer master sign-off by Group Financial Controller | D12: 46434.708 | E12: =D12+F12/24 -> 46434.875 | F12: 4 | G12: CUT-009 | H12: Hassan Ali | I12: Zava Finance | J12: Not started | K12: Signed master data sign-off
A13: CUT-011 | B13: Pre-cutover (T-14 to T-1) | C13: Fixed asset register loaded and reconciled | D13: 46434.875 | E13: =D13+F13/24 -> 46435.208 | F13: 8 | G13: CUT-010 | H13: James Okafor | I13: Frontier – Finance | J13: Not started | K13: FA reconciliation
A14: CUT-012 | B14: Pre-cutover (T-14 to T-1) | C14: Warehouse locations, zones and license plates set up | D14: 46434.375 | E14: =D14+F14/24 -> 46434.875 | F14: 12 | G14: CUT-007 | H14: Rahul Verma | I14: Frontier – Supply Chain | J14: Not started | K14: Location count report
A15: CUT-013 | B15: Pre-cutover (T-14 to T-1) | C15: Warehouse mobile devices configured and tested on production | D15: 46435.375 | E15: =D15+F15/24 -> 46435.708 | F15: 8 | G15: CUT-012 | H15: Grace Lee | I15: Zava Warehouse | J15: Not started | K15: Device test checklist
A16: CUT-014 | B16: Pre-cutover (T-14 to T-1) | C16: Trade agreements and freight rate cards loaded | D16: 46434.375 | E16: =D16+F16/24 -> 46434.708 | F16: 8 | G16: CUT-007 | H16: Lina Mansour | I16: Frontier – CE | J16: Not started | K16: Rate card comparison
A17: CUT-015 | B17: Pre-cutover (T-14 to T-1) | C17: CargoWise production connection tested (read-only) | D17: 46435.375 | E17: =D17+F17/24 -> 46435.625 | F17: 6 | G17: CUT-003 | H17: Arjun Mehta | I17: Frontier – Integration | J17: Not started | K17: Connection test log
A18: CUT-016 | B18: Pre-cutover (T-14 to T-1) | C18: ZATCA e-invoicing ISV production onboarding for ZVSA | D18: 46435.625 | E18: =D18+F18/24 -> 46435.958 | F18: 8 | G18: CUT-015 | H18: James Okafor | I18: Frontier – Finance | J18: Not started | K18: ZATCA onboarding certificate (CSID)
A19: CUT-017 | B19: Pre-cutover (T-14 to T-1) | C19: Bank integration production certificates installed (UAE, KSA, Oman) | D19: 46435.958 | E19: =D19+F19/24 -> 46436.208 | F19: 6 | G19: CUT-016 | H19: Ravi Kumar | I19: Zava IT | J19: Not started | K19: Certificate install log
A20: CUT-018 | B20: Pre-cutover (T-14 to T-1) | C20: Batch jobs created (disabled) and schedule documented | D20: 46436.375 | E20: =D20+F20/24 -> 46436.625 | F20: 6 | G20: CUT-003 | H20: Arjun Mehta | I20: Frontier – Integration | J20: Not started | K20: Batch job list
A21: CUT-019 | B21: Pre-cutover (T-14 to T-1) | C21: Printer and label configuration for warehouse documents | D21: 46436.625 | E21: =D21+F21/24 -> 46436.792 | F21: 4 | G21: CUT-018 | H21: Ravi Kumar | I21: Zava IT | J21: Not started | K21: Test print evidence
A22: CUT-020 | B22: Pre-cutover (T-14 to T-1) | C22: End-user training completion confirmed (>= 90%) | D22: 46436.375 | E22: =D22+F22/24 -> 46436.542 | F22: 4 | H22: Tom Becker | I22: Frontier – Change | J22: Not started | K22: Training completion report
A23: CUT-021 | B23: Pre-cutover (T-14 to T-1) | C23: Go-live communications issued to staff and customers | D23: 46436.542 | E23: =D23+F23/24 -> 46436.625 | F23: 2 | G23: CUT-020 | H23: Elena Petrova | I23: Zava HR & Change | J23: Not started | K23: Comms email and intranet post
A24: CUT-022 | B24: Pre-cutover (T-14 to T-1) | C24: Legacy GP 2018 and Tally period-end close completed (Jan 2027) | D24: 46437.375 | E24: =D24+F24/24 -> 46438.042 | F24: 16 | H24: Hassan Ali | I24: Zava Finance | J24: Not started | K24: Close checklist
A25: CUT-023 | B25: Pre-cutover (T-14 to T-1) | C25: Hypercare support model and ticket queues ready | D25: 46440.375 | E25: =D25+F25/24 -> 46440.542 | F25: 4 | H25: Priya Nair | I25: PMO | J25: Not started | K25: Hypercare runbook
A26: CUT-024 | B26: Pre-cutover (T-14 to T-1) | C26: Cutover rehearsal walkthrough (table-top) | D26: 46441.417 | E26: =D26+F26/24 -> 46441.542 | F26: 3 | G26: CUT-002 | H26: Priya Nair | I26: PMO | J26: Not started | K26: Attendance and actions
A27: CUT-025 | B27: Pre-cutover (T-14 to T-1) | C27: Open items extract scripts validated against Mock 3 | D27: 46441.583 | E27: =D27+F27/24 -> 46441.75 | F27: 4 | G27: CUT-006 | H27: Noura Al Hashimi | I27: Frontier – Data | J27: Not started | K27: Script sign-off
A28: CUT-026 | B28: Pre-cutover (T-14 to T-1) | C28: Customer and vendor notification of new bank details/invoice format | D28: 46441.75 | E28: =D28+F28/24 -> 46441.917 | F28: 4 | G28: CUT-025 | H28: Samir Haddad | I28: Zava Customer Service | J28: Not started | K28: Notification log
A29: CUT-027 | B29: Pre-cutover (T-14 to T-1) | C29: Readiness checkpoint with sponsor (T-2) | D29: 46442.458 | E29: =D29+F29/24 -> 46442.5 | F29: 1 | G29: CUT-024, CUT-025 | H29: Nadia Farouk | I29: Zava Sponsor | J29: Not started | K29: Readiness checklist | L29: T-2
A30: CUT-028 | B30: Pre-cutover (T-14 to T-1) | C30: Final backup of legacy systems scheduled | D30: 46443.375 | E30: =D30+F30/24 -> 46443.458 | F30: 2 | H30: Ravi Kumar | I30: Zava IT | J30: Not started | K30: Backup schedule
A31: CUT-029 | B31: Freeze | C31: Freeze new sales quotes and orders in Salesforce / legacy | D31: 46444.5 | E31: =D31+F31/24 -> 46444.542 | F31: 1 | G31: CUT-027 | H31: Lina Mansour | I31: Frontier – CE | J31: Not started | K31: Freeze confirmation email
A32: CUT-030 | B32: Freeze | C32: Freeze AP invoice entry in GP 2018 and Tally | D32: 46444.5 | E32: =D32+F32/24 -> 46444.542 | F32: 1 | G32: CUT-027 | H32: Hassan Ali | I32: Zava Finance | J32: Not started | K32: Freeze confirmation
A33: CUT-031 | B33: Freeze | C33: Freeze AR invoicing and cash receipts in legacy | D33: 46444.5 | E33: =D33+F33/24 -> 46444.542 | F33: 1 | G33: CUT-027 | H33: Hassan Ali | I33: Zava Finance | J33: Not started | K33: Freeze confirmation
A34: CUT-032 | B34: Freeze | C34: Freeze warehouse transactions in legacy WMS (stock count start) | D34: 46444.542 | E34: =D34+F34/24 -> 46444.583 | F34: 1 | G34: CUT-027 | H34: Grace Lee | I34: Zava Warehouse | J34: Not started | K34: Freeze confirmation
A35: CUT-033 | B35: Freeze | C35: CargoWise outbound messages paused | D35: 46444.542 | E35: =D35+F35/24 -> 46444.583 | F35: 1 | G35: CUT-027 | H35: Arjun Mehta | I35: Frontier – Integration | J35: Not started | K35: Queue screenshot
A36: CUT-034 | B36: Freeze | C36: Physical stock count at Jebel Ali DC | D36: 46444.583 | E36: =D36+F36/24 -> 46444.75 | F36: 4 | G36: CUT-033 | H36: Grace Lee | I36: Zava Warehouse | J36: Not started | K36: Signed count sheets
A37: CUT-035 | B37: Freeze | C37: Legacy systems set to read-only | D37: 46444.583 | E37: =D37+F37/24 -> 46444.625 | F37: 1 | G37: CUT-029, CUT-030, CUT-031 | H37: Ravi Kumar | I37: Zava IT | J37: Not started | K37: Access change record
A38: CUT-036 | B38: Freeze | C38: Final legacy backups taken | D38: 46444.625 | E38: =D38+F38/24 -> 46444.708 | F38: 2 | G38: CUT-035 | H38: Ravi Kumar | I38: Zava IT | J38: Not started | K38: Backup log
A39: CUT-037 | B39: Freeze | C39: Closing trial balances extracted per entity (ZVAE, ZVSA, ZVOM, ZVQA, ZVHQ) | D39: 46444.708 | E39: =D39+F39/24 -> 46444.792 | F39: 2 | G39: CUT-036 | H39: James Okafor | I39: Frontier – Finance | J39: Not started | K39: Trial balance extracts
A40: CUT-038 | B40: Freeze | C40: Freeze confirmation to cutover lead | D40: 46444.792 | E40: =D40+F40/24 -> 46444.813 | F40: 0.5 | G40: CUT-034, CUT-037 | H40: Priya Nair | I40: PMO | J40: Not started | K40: Teams post in cutover channel
...

Sheet Phase summary
A1: ZAV-HZN cutover phase summary | Fictitious test data – Copilot for Frontier Consultancy scenario testing
A2: Phase | B2: Tasks | C2: Earliest start | D2: Latest finish | E2: Total task hours | F2: Elapsed hours
A3: Pre-cutover (T-14 to T-1) | B3: =COUNTIFS('Runbook'!$B$3:$B$114,A3) -> 28 | C3: =_xlfn.MINIFS('Runbook'!$D$3:$D$114,'Runbook'!$B$3:$B$114,A3) -> 46430.375 | D3: =_xlfn.MAXIFS('Runbook'!$E$3:$E$114,'Runbook'!$B$3:$B$114,A3) -> 46443.458 | E3: =SUMIFS('Runbook'!$F$3:$F$114,'Runbook'!$B$3:$B$114,A3) -> 182 | F3: =(D3-C3)*24 -> 314
A4: Freeze | B4: =COUNTIFS('Runbook'!$B$3:$B$114,A4) -> 10 | C4: =_xlfn.MINIFS('Runbook'!$D$3:$D$114,'Runbook'!$B$3:$B$114,A4) -> 46444.5 | D4: =_xlfn.MAXIFS('Runbook'!$E$3:$E$114,'Runbook'!$B$3:$B$114,A4) -> 46444.813 | E4: =SUMIFS('Runbook'!$F$3:$F$114,'Runbook'!$B$3:$B$114,A4) -> 14.5 | F4: =(D4-C4)*24 -> 7.500008
A5: Data migration | B5: =COUNTIFS('Runbook'!$B$3:$B$114,A5) -> 22 | C5: =_xlfn.MINIFS('Runbook'!$D$3:$D$114,'Runbook'!$B$3:$B$114,A5) -> 46444.854 | D5: =_xlfn.MAXIFS('Runbook'!$E$3:$E$114,'Runbook'!$B$3:$B$114,A5) -> 46445.417 | E5: =SUMIFS('Runbook'!$F$3:$F$114,'Runbook'!$B$3:$B$114,A5) -> 41.5 | F5: =(D5-C5)*24 -> 13.499992
A6: Technical | B6: =COUNTIFS('Runbook'!$B$3:$B$114,A6) -> 12 | C6: =_xlfn.MINIFS('Runbook'!$D$3:$D$114,'Runbook'!$B$3:$B$114,A6) -> 46445.417 | D6: =_xlfn.MAXIFS('Runbook'!$E$3:$E$114,'Runbook'!$B$3:$B$114,A6) -> 46445.646 | E6: =SUMIFS('Runbook'!$F$3:$F$114,'Runbook'!$B$3:$B$114,A6) -> 14 | F6: =(D6-C6)*24 -> 5.499992
A7: Business validation | B7: =COUNTIFS('Runbook'!$B$3:$B$114,A7) -> 15 | C7: =_xlfn.MINIFS('Runbook'!$D$3:$D$114,'Runbook'!$B$3:$B$114,A7) -> 46445.708 | D7: =_xlfn.MAXIFS('Runbook'!$E$3:$E$114,'Runbook'!$B$3:$B$114,A7) -> 46446.125 | E7: =SUMIFS('Runbook'!$F$3:$F$114,'Runbook'!$B$3:$B$114,A7) -> 32.5 | F7: =(D7-C7)*24 -> 10.000016
A8: Go/No-Go gates | B8: =COUNTIFS('Runbook'!$B$3:$B$114,A8) -> 7 | C8: =_xlfn.MINIFS('Runbook'!$D$3:$D$114,'Runbook'!$B$3:$B$114,A8) -> 46444.812 | D8: =_xlfn.MAXIFS('Runbook'!$E$3:$E$114,'Runbook'!$B$3:$B$114,A8) -> 46446.729 | E8: =SUMIFS('Runbook'!$F$3:$F$114,'Runbook'!$B$3:$B$114,A8) -> 5 | F8: =(D8-C8)*24 -> 45.999992
A9: Go-live | B9: =COUNTIFS('Runbook'!$B$3:$B$114,A9) -> 8 | C9: =_xlfn.MINIFS('Runbook'!$D$3:$D$114,'Runbook'!$B$3:$B$114,A9) -> 46446.729 | D9: =_xlfn.MAXIFS('Runbook'!$E$3:$E$114,'Runbook'!$B$3:$B$114,A9) -> 46447.354 | E9: =SUMIFS('Runbook'!$F$3:$F$114,'Runbook'!$B$3:$B$114,A9) -> 5.5 | F9: =(D9-C9)*24 -> 14.999984
A10: Hypercare day 1 | B10: =COUNTIFS('Runbook'!$B$3:$B$114,A10) -> 10 | C10: =_xlfn.MINIFS('Runbook'!$D$3:$D$114,'Runbook'!$B$3:$B$114,A10) -> 46447.292 | D10: =_xlfn.MAXIFS('Runbook'!$E$3:$E$114,'Runbook'!$B$3:$B$114,A10) -> 46447.833 | E10: =SUMIFS('Runbook'!$F$3:$F$114,'Runbook'!$B$3:$B$114,A10) -> 41 | F10: =(D10-C10)*24 -> 13
A11: Total | B11: =SUM(B3:B10) -> 112 | C11: =MIN(C3:C10) -> 46430.375 | D11: =MAX(D3:D10) -> 46447.833 | E11: =SUM(E3:E10) -> 336 | F11: =(D11-C11)*24 -> 419.00001
