Workbook
Name AsOfDate: 'Read me'!$B$7

Sheet Read me
A1: ZAV-HZN Sprint Backlog Export
A2: Fictitious test data – Copilot for Frontier Consultancy scenario testing
A4: Purpose | B4: Azure DevOps-style work item export for the Zava Horizon Build phase (Sprints 3–5). Use for testing sprint status summaries, blocker analysis (CargoWise), velocity and burndown questions, and stand-up preparation.
A5: Programme | B5: Zava Horizon (ZAV-HZN) – Zava LLC, delivered by Frontier Consulting
A6: Data as of | B6: Monday 19 Oct 2026 (Dubai, UTC+4)
A7: As-of date (used in formulas) | B7: 46314
A8: Currency | B8: AED
A9: Prepared by | B9: Priya Nair, Project Manager (Frontier Consulting) – scenario owner Lorette Roos
A11: Sheet | B11: Contents
A12: Backlog | B12: 90 work items (Epics, Features, User Stories, Bugs, Tasks) exported from Azure DevOps project ZAV-HZN. Epics and Features sit at release level.
A13: Sprint summary | B13: Story points and item counts by sprint and state, Sprint 4 completion % and blocked counts (formulas).
A15: Sprint calendar | B15: Sprint 3: Mon 28 Sep – Fri 9 Oct 2026 | Sprint 4: Mon 12 Oct – Fri 23 Oct 2026 | Sprint 5: Mon 26 Oct – Fri 6 Nov 2026
A16: Completion rule | B16: Completed = State Resolved or Closed; completion % measured on story points.
A18: Important | B18: Fictitious test data – Copilot for Frontier Consultancy scenario testing. All companies, people and figures are fictitious and must not be used for real decisions.

Sheet Backlog
A1: ZAV-HZN Sprint Backlog Export (Azure DevOps) | Fictitious test data – Copilot for Frontier Consultancy scenario testing
A2: ID | B2: Work item type | C2: Title | D2: Workstream | E2: Assigned to | F2: State | G2: Sprint | H2: Story points | I2: Remaining work | J2: Tags | K2: Changed date
A3: 4101 | B3: Epic | C3: Finance core – GL, AP, AR, fixed assets for five legal entities | D3: Finance | E3: James Okafor | F3: Active | G3: ZAV-HZN\Release 1 | J3: fin | K3: 46300.425
A4: 4102 | B4: Epic | C4: Warehouse management and transport for Jebel Ali operations | D4: Supply Chain/Warehousing | E4: Rahul Verma | F4: Active | G4: ZAV-HZN\Release 1 | J4: scm | K4: 46300.425
A5: 4103 | B5: Epic | C5: Sales and Customer Service on Dynamics 365 CE | D5: Sales & Service CE | E5: Lina Mansour | F5: Active | G5: ZAV-HZN\Release 1 | J5: ce | K5: 46300.425
A6: 4104 | B6: Epic | C6: Data migration from Dynamics GP 2018 and Tally | D6: Data Migration | E6: Noura Al Hashimi | F6: Active | G6: ZAV-HZN\Release 1 | J6: dm | K6: 46300.425
A7: 4105 | B7: Epic | C7: Integrations – CargoWise, banks, ZATCA, Azure Integration Services | D7: Integration | E7: Arjun Mehta | F7: Active | G7: ZAV-HZN\Release 1 | J7: int | K7: 46300.425
A8: 4106 | B8: Epic | C8: M365 Copilot rollout – 600 licences | D8: Change & Copilot Adoption | E8: Tom Becker | F8: Active | G8: ZAV-HZN\Release 1 | J8: chg | K8: 46300.425
A9: 4107 | B9: Feature | C9: Intercompany accounting ZVAE/ZVSA/ZVOM/ZVQA/ZVHQ | D9: Finance | E9: James Okafor | F9: Active | G9: ZAV-HZN\Release 1 | J9: fin | K9: 46303.653
A10: 4108 | B10: Feature | C10: ZATCA e-invoicing for ZVSA | D10: Finance | E10: James Okafor | F10: Active | G10: ZAV-HZN\Release 1 | J10: fin | K10: 46303.653
A11: 4109 | B11: Feature | C11: Bank statement and payment integration | D11: Finance | E11: James Okafor | F11: Active | G11: ZAV-HZN\Release 1 | J11: fin | K11: 46303.653
A12: 4110 | B12: Feature | C12: Mobile warehouse app – receiving and putaway | D12: Supply Chain/Warehousing | E12: Rahul Verma | F12: Active | G12: ZAV-HZN\Release 1 | J12: scm | K12: 46303.653
A13: 4111 | B13: Feature | C13: Trade agreements and freight rate cards | D13: Supply Chain/Warehousing | E13: Rahul Verma | F13: Active | G13: ZAV-HZN\Release 1 | J13: scm | K13: 46303.653
A14: 4112 | B14: Feature | C14: Lead-to-quote for freight forwarding | D14: Sales & Service CE | E14: Lina Mansour | F14: Active | G14: ZAV-HZN\Release 1 | J14: ce | K14: 46303.653
... A22: 4120 | B22: Feature | C22: Financial reporting and Power BI | D22: Finance | E22: James Okafor | F22: New | G22: ZAV-HZN\Release 1 | J22: fin | K22: 46303.653
A23: 4121 | B23: User Story | C23: GL chart of accounts and main account structure for ZVAE | D23: Finance | E23: James Okafor | F23: Closed | G23: ZAV-HZN\Sprint 3 | H23: 5 | J23: fin | K23: 46296.375
A24: 4122 | B24: User Story | C24: Financial dimensions: entity, department, cost centre, trade lane | D24: Finance | E24: James Okafor | F24: Closed | G24: ZAV-HZN\Sprint 3 | H24: 3 | J24: fin | K24: 46297.422
A25: 4123 | B25: User Story | C25: AP invoice approval workflow with 3-way match | D25: Finance | E25: James Okafor | F25: Closed | G25: ZAV-HZN\Sprint 3 | H25: 5 | J25: fin | K25: 46298.468
A26: 4124 | B26: Task | C26: Configure number sequences for five legal entities | D26: Finance | E26: Arjun Mehta | F26: Closed | G26: ZAV-HZN\Sprint 3 | I26: 0 | J26: fin | K26: 46299.515
A27: 4125 | B27: User Story | C27: Warehouse locations and zones for Jebel Ali DC | D27: Supply Chain/Warehousing | E27: Rahul Verma | F27: Closed | G27: ZAV-HZN\Sprint 3 | H27: 5 | J27: scm | K27: 46300.561
A28: 4126 | B28: User Story | C28: Inbound receiving by license plate | D28: Supply Chain/Warehousing | E28: Rahul Verma | F28: Closed | G28: ZAV-HZN\Sprint 3 | H28: 8 | J28: scm | K28: 46301.608
A29: 4127 | B29: Bug | C29: Location directive picks wrong zone for bonded stock | D29: Supply Chain/Warehousing | E29: Rahul Verma | F29: Closed | G29: ZAV-HZN\Sprint 3 | H29: 2 | J29: scm | K29: 46302.654
A30: 4128 | B30: User Story | C30: Account and contact model for shippers and consignees | D30: Sales & Service CE | E30: Lina Mansour | F30: Closed | G30: ZAV-HZN\Sprint 3 | H30: 3 | J30: ce | K30: 46303.701
A31: 4129 | B31: User Story | C31: Opportunity stages for freight forwarding deals | D31: Sales & Service CE | E31: Lina Mansour | F31: Closed | G31: ZAV-HZN\Sprint 3 | H31: 3 | J31: ce | K31: 46304.414
A32: 4130 | B32: User Story | C32: Case categories and queues for three-shift model | D32: Sales & Service CE | E32: Lina Mansour | F32: Closed | G32: ZAV-HZN\Sprint 3 | H32: 5 | J32: ce | K32: 46296.419
A33: 4131 | B33: Task | C33: SLA KPI configuration for first response | D33: Sales & Service CE | E33: Lina Mansour | F33: Resolved | G33: ZAV-HZN\Sprint 3 | I33: 0 | J33: ce | K33: 46297.465
A34: 4132 | B34: User Story | C34: Vendor master profiling – GP 2018 and Tally | D34: Data Migration | E34: Noura Al Hashimi | F34: Closed | G34: ZAV-HZN\Sprint 3 | H34: 5 | J34: dm | K34: 46298.512
A35: 4133 | B35: Task | C35: Data migration framework – staging database | D35: Data Migration | E35: Noura Al Hashimi | F35: Closed | G35: ZAV-HZN\Sprint 3 | I35: 0 | J35: dm | K35: 46299.558
A36: 4134 | B36: User Story | C36: Customer master mapping template | D36: Data Migration | E36: Noura Al Hashimi | F36: Closed | G36: ZAV-HZN\Sprint 3 | H36: 3 | J36: dm | K36: 46300.605
A37: 4135 | B37: User Story | C37: Azure Service Bus topics and subscriptions | D37: Integration | E37: Arjun Mehta | F37: Closed | G37: ZAV-HZN\Sprint 3 | H37: 5 | J37: int | K37: 46301.651
A38: 4136 | B38: Task | C38: Key Vault and managed identity setup | D38: Integration | E38: Arjun Mehta | F38: Closed | G38: ZAV-HZN\Sprint 3 | I38: 0 | J38: int | K38: 46302.698
A39: 4137 | B39: User Story | C39: CargoWise interface design (draft spec) | D39: Integration | E39: Arjun Mehta | F39: Resolved | G39: ZAV-HZN\Sprint 3 | H39: 5 | J39: int | K39: 46303.411
A40: 4138 | B40: User Story | C40: Copilot pilot onboarding – 120 users | D40: Change & Copilot Adoption | E40: Tom Becker | F40: Closed | G40: ZAV-HZN\Sprint 3 | H40: 3 | J40: chg | K40: 46304.458
A41: 4139 | B41: User Story | C41: SharePoint oversharing scan – 60 sites | D41: Change & Copilot Adoption | E41: Tom Becker | F41: Closed | G41: ZAV-HZN\Sprint 3 | H41: 3 | J41: chg | K41: 46296.463
A42: 4140 | B42: Bug | C42: Posting profile error on ZVOM vendor invoices | D42: Finance | E42: James Okafor | F42: Closed | G42: ZAV-HZN\Sprint 3 | H42: 2 | J42: fin | K42: 46297.509
A43: 4141 | B43: Task | C43: Sprint 3 demo and retrospective | D43: Finance | E43: Priya Nair | F43: Closed | G43: ZAV-HZN\Sprint 3 | I43: 0 | J43: fin | K43: 46298.556
A44: 4142 | B44: User Story | C44: Fixed asset groups and depreciation profiles | D44: Finance | E44: James Okafor | F44: Closed | G44: ZAV-HZN\Sprint 3 | H44: 5 | J44: fin | K44: 46299.602
A45: 4143 | B45: User Story | C45: Intercompany journal auto-posting ZVAE to ZVSA | D45: Finance | E45: James Okafor | F45: Closed | G45: ZAV-HZN\Sprint 4 | H45: 8 | I45: 0 | J45: fin; intercompany | K45: 46307.375
A46: 4144 | B46: User Story | C46: Intercompany due-to/due-from settlement rules | D46: Finance | E46: James Okafor | F46: Closed | G46: ZAV-HZN\Sprint 4 | H46: 5 | I46: 0 | J46: fin; intercompany | K46: 46308.426
A47: 4145 | B47: User Story | C47: AR customer invoicing with freight charge codes | D47: Finance | E47: James Okafor | F47: Closed | G47: ZAV-HZN\Sprint 4 | H47: 8 | I47: 0 | J47: fin | K47: 46309.476
...

Sheet Sprint summary
A1: ZAV-HZN sprint summary | Fictitious test data – Copilot for Frontier Consultancy scenario testing
A2: Sprint | B2: Items | C2: Story points (total) | D2: Points – New | E2: Points – Active | F2: Points – Resolved | G2: Points – Closed | H2: Points – Blocked | I2: Points completed | J2: Completion % | K2: Blocked items | L2: Remaining work (h)
A3: ZAV-HZN\Sprint 3 | B3: =COUNTIFS(Backlog!$G$3:$G$92,$A3) -> 22 | C3: =SUMIFS(Backlog!$H$3:$H$92,Backlog!$G$3:$G$92,$A3) -> 70 | D3: =SUMIFS(Backlog!$H$3:$H$92,Backlog!$G$3:$G$92,$A3,Backlog!$F$3:$F$92,"New") -> 0 | E3: =SUMIFS(Backlog!$H$3:$H$92,Backlog!$G$3:$G$92,$A3,Backlog!$F$3:$F$92,"Active") -> 0 | F3: =SUMIFS(Backlog!$H$3:$H$92,Backlog!$G$3:$G$92,$A3,Backlog!$F$3:$F$92,"Resolved") -> 5 | G3: =SUMIFS(Backlog!$H$3:$H$92,Backlog!$G$3:$G$92,$A3,Backlog!$F$3:$F$92,"Closed") -> 65 | H3: =SUMIFS(Backlog!$H$3:$H$92,Backlog!$G$3:$G$92,$A3,Backlog!$F$3:$F$92,"Blocked") -> 0 | I3: =F3+G3 -> 70 | J3: =IF(C3=0,0,I3/C3) -> 1 | K3: =COUNTIFS(Backlog!$G$3:$G$92,$A3,Backlog!$F$3:$F$92,"Blocked") -> 0 | L3: =SUMIFS(Backlog!$I$3:$I$92,Backlog!$G$3:$G$92,$A3) -> 0
A4: ZAV-HZN\Sprint 4 | B4: =COUNTIFS(Backlog!$G$3:$G$92,$A4) -> 28 | C4: =SUMIFS(Backlog!$H$3:$H$92,Backlog!$G$3:$G$92,$A4) -> 100 | D4: =SUMIFS(Backlog!$H$3:$H$92,Backlog!$G$3:$G$92,$A4,Backlog!$F$3:$F$92,"New") -> 6 | E4: =SUMIFS(Backlog!$H$3:$H$92,Backlog!$G$3:$G$92,$A4,Backlog!$F$3:$F$92,"Active") -> 6 | F4: =SUMIFS(Backlog!$H$3:$H$92,Backlog!$G$3:$G$92,$A4,Backlog!$F$3:$F$92,"Resolved") -> 13 | G4: =SUMIFS(Backlog!$H$3:$H$92,Backlog!$G$3:$G$92,$A4,Backlog!$F$3:$F$92,"Closed") -> 57 | H4: =SUMIFS(Backlog!$H$3:$H$92,Backlog!$G$3:$G$92,$A4,Backlog!$F$3:$F$92,"Blocked") -> 18 | I4: =F4+G4 -> 70 | J4: =IF(C4=0,0,I4/C4) -> 0.7 | K4: =COUNTIFS(Backlog!$G$3:$G$92,$A4,Backlog!$F$3:$F$92,"Blocked") -> 6 | L4: =SUMIFS(Backlog!$I$3:$I$92,Backlog!$G$3:$G$92,$A4) -> 38
A5: ZAV-HZN\Sprint 5 | B5: =COUNTIFS(Backlog!$G$3:$G$92,$A5) -> 20 | C5: =SUMIFS(Backlog!$H$3:$H$92,Backlog!$G$3:$G$92,$A5) -> 89 | D5: =SUMIFS(Backlog!$H$3:$H$92,Backlog!$G$3:$G$92,$A5,Backlog!$F$3:$F$92,"New") -> 89 | E5: =SUMIFS(Backlog!$H$3:$H$92,Backlog!$G$3:$G$92,$A5,Backlog!$F$3:$F$92,"Active") -> 0 | F5: =SUMIFS(Backlog!$H$3:$H$92,Backlog!$G$3:$G$92,$A5,Backlog!$F$3:$F$92,"Resolved") -> 0 | G5: =SUMIFS(Backlog!$H$3:$H$92,Backlog!$G$3:$G$92,$A5,Backlog!$F$3:$F$92,"Closed") -> 0 | H5: =SUMIFS(Backlog!$H$3:$H$92,Backlog!$G$3:$G$92,$A5,Backlog!$F$3:$F$92,"Blocked") -> 0 | I5: =F5+G5 -> 0 | J5: =IF(C5=0,0,I5/C5) -> 0 | K5: =COUNTIFS(Backlog!$G$3:$G$92,$A5,Backlog!$F$3:$F$92,"Blocked") -> 0 | L5: =SUMIFS(Backlog!$I$3:$I$92,Backlog!$G$3:$G$92,$A5) -> 16
A6: Total (Sprints 3–5) | B6: =SUM(B3:B5) -> 70 | C6: =SUM(C3:C5) -> 259 | D6: =SUM(D3:D5) -> 95 | E6: =SUM(E3:E5) -> 6 | F6: =SUM(F3:F5) -> 18 | G6: =SUM(G3:G5) -> 122 | H6: =SUM(H3:H5) -> 18 | I6: =SUM(I3:I5) -> 140 | J6: =IF(C6=0,0,I6/C6) -> 0.54054054 | K6: =SUM(K3:K5) -> 6 | L6: =SUM(L3:L5) -> 54
A8: Sprint 4 blocked items tagged CargoWise | B8: =COUNTIFS(Backlog!$F$3:$F$92,"Blocked",Backlog!$J$3:$J$92,"*CargoWise*") -> 6
A9: Sprint 4 end date | B9: 46318
A10: Check: items on Backlog (all sprints + release) | B10: =COUNTA(Backlog!$A$3:$A$92) -> 90
