Workbook
Name AsOfDate: 'Read me'!$B$7

Sheet Read me
A1: ZAV-HZN Action Tracker
A2: Fictitious test data – Copilot for Frontier Consultancy scenario testing
A4: Purpose | B4: Meeting action log for the Zava Horizon programme, captured from daily stand-ups (09:15), design authority (Tue 14:00), PMO status (Thu 11:00) and monthly SteerCo. Use for testing overdue-action chasing, owner follow-ups, meeting preparation and status summaries.
A5: Programme | B5: Zava Horizon (ZAV-HZN) – Zava LLC, delivered by Frontier Consulting
A6: Data as of | B6: Monday 19 Oct 2026 (Dubai, UTC+4)
A7: As-of date (used in formulas) | B7: 46314
A8: Currency | B8: AED
A9: Prepared by | B9: Priya Nair, Project Manager (Frontier Consulting) – scenario owner Lorette Roos
A11: Sheet | B11: Contents
A12: Actions | B12: 40 actions with meeting, owner, due date, status and notes. 'Days overdue' and 'Overdue?' are calculated against the as-of date above.
A13: Summary | B13: Open, closed and overdue counts by meeting and by owner (formulas).
A15: Overdue rule | B15: Overdue = status not Closed and due date before the as-of date (19 Oct 2026).
A16: Next SteerCo | B16: Wed 28 Oct 2026 10:00–11:30 (previous: 30 Sep 2026)
A18: Important | B18: Fictitious test data – Copilot for Frontier Consultancy scenario testing. All companies, people and figures are fictitious and must not be used for real decisions.

Sheet Actions
A1: ZAV-HZN Action Tracker | Fictitious test data – Copilot for Frontier Consultancy scenario testing
A2: Action ID | B2: Meeting | C2: Meeting date | D2: Action | E2: Owner | F2: Due date | G2: Status | H2: Closed date | I2: Notes | J2: Days overdue | K2: Overdue?
A3: ACT-001 | B3: SteerCo | C3: 46260 | D3: Confirm approach for ZATCA e-invoicing for ZVSA (ISV vs native) | E3: James Okafor | F3: 46281 | G3: Closed | H3: 46280 | I3: Options paper issued; ISV route recommended. Decision on which ISV still open (see RAID I-002). | J3: =IF(AND(G3<>"Closed",F3<AsOfDate),AsOfDate-F3,"") | K3: =IF(AND(G3<>"Closed",F3<AsOfDate),"Yes","No") -> No
A4: ACT-002 | B4: SteerCo | C4: 46260 | D4: Nominate Zava SME for each workstream for Build | E4: Elena Petrova | F4: 46269 | G4: Closed | H4: 46268 | I4: Names confirmed in PMO status 3 Sep. | J4: =IF(AND(G4<>"Closed",F4<AsOfDate),AsOfDate-F4,"") | K4: =IF(AND(G4<>"Closed",F4<AsOfDate),"Yes","No") -> No
A5: ACT-003 | B5: SteerCo | C5: 46260 | D5: Approve design sign-off plan for 4 Sep | E5: Nadia Farouk | F5: 46269 | G5: Closed | H5: 46269 | I5: Design signed off 4 Sep 2026. | J5: =IF(AND(G5<>"Closed",F5<AsOfDate),AsOfDate-F5,"") | K5: =IF(AND(G5<>"Closed",F5<AsOfDate),"Yes","No") -> No
A6: ACT-004 | B6: SteerCo | C6: 46295 | D6: Escalate CargoWise API specification delay to vendor executive sponsor | E6: Ravi Kumar | F6: 46302 | G6: In progress | I6: Letter drafted; vendor call held 9 Oct but no committed date yet. | J6: =IF(AND(G6<>"Closed",F6<AsOfDate),AsOfDate-F6,"") -> 12 | K6: =IF(AND(G6<>"Closed",F6<AsOfDate),"Yes","No") -> Yes
A7: ACT-005 | B7: SteerCo | C7: 46295 | D7: Decide ZATCA ISV for ZVSA | E7: Nadia Farouk | F7: 46309 | G7: Open | I7: Two ISVs shortlisted; awaiting commercial comparison from Hassan Ali. | J7: =IF(AND(G7<>"Closed",F7<AsOfDate),AsOfDate-F7,"") -> 5 | K7: =IF(AND(G7<>"Closed",F7<AsOfDate),"Yes","No") -> Yes
A8: ACT-006 | B8: SteerCo | C8: 46295 | D8: Bring options for UAT clash with ZVQA year-end close | E8: Priya Nair | F8: 46316 | G8: In progress | I8: Two options drafted: split UAT or move ZVQA scripts into SIT week 3. | J8: =IF(AND(G8<>"Closed",F8<AsOfDate),AsOfDate-F8,"") | K8: =IF(AND(G8<>"Closed",F8<AsOfDate),"Yes","No") -> No
A9: ACT-007 | B9: SteerCo | C9: 46295 | D9: Present CR-007, CR-008 and CR-009 with impact and cost | E9: Priya Nair | F9: 46316 | G9: In progress | I9: CR-007 18 days; CR-008 45 days; CR-009 saves 12 days (pricing risk). | J9: =IF(AND(G9<>"Closed",F9<AsOfDate),AsOfDate-F9,"") | K9: =IF(AND(G9<>"Closed",F9<AsOfDate),"Yes","No") -> No
A10: ACT-008 | B10: SteerCo | C10: 46295 | D10: Approve contingency drawdown CD-01 for CargoWise rework (AED 120,000) | E10: Nadia Farouk | F10: 46295 | G10: Closed | H10: 46295 | I10: Approved in meeting. | J10: =IF(AND(G10<>"Closed",F10<AsOfDate),AsOfDate-F10,"") | K10: =IF(AND(G10<>"Closed",F10<AsOfDate),"Yes","No") -> No
A11: ACT-009 | B11: PMO status | C11: 46282 | D11: Share revised spend forecast after August actuals | E11: Priya Nair | F11: 46289 | G11: Closed | H11: 46289 | I11: Spend running 7% ahead of plan. | J11: =IF(AND(G11<>"Closed",F11<AsOfDate),AsOfDate-F11,"") | K11: =IF(AND(G11<>"Closed",F11<AsOfDate),"Yes","No") -> No
A12: ACT-010 | B12: PMO status | C12: 46289 | D12: Provide warehouse handheld device decision (Zebra vs Honeywell) | E12: Grace Lee | F12: 46303 | G12: Open | I12: Comparison sent 18 Sep; chased twice. | J12: =IF(AND(G12<>"Closed",F12<AsOfDate),AsOfDate-F12,"") -> 11 | K12: =IF(AND(G12<>"Closed",F12<AsOfDate),"Yes","No") -> Yes
A13: ACT-011 | B13: PMO status | C13: 46289 | D13: Provision Azure integration environment (Logic Apps, Service Bus, Key Vault) in Zava tenant | E13: Ravi Kumar | F13: 46296 | G13: In progress | I13: Service Bus done; Logic Apps pending firewall rules. | J13: =IF(AND(G13<>"Closed",F13<AsOfDate),AsOfDate-F13,"") -> 18 | K13: =IF(AND(G13<>"Closed",F13<AsOfDate),"Yes","No") -> Yes
A14: ACT-012 | B14: PMO status | C14: 46296 | D14: Confirm Copilot licence assignment report for all 600 users | E14: Ravi Kumar | F14: 46303 | G14: Open | I14: Needed before training wave 2. | J14: =IF(AND(G14<>"Closed",F14<AsOfDate),AsOfDate-F14,"") -> 11 | K14: =IF(AND(G14<>"Closed",F14<AsOfDate),"Yes","No") -> Yes
A15: ACT-013 | B15: PMO status | C15: 46296 | D15: Circulate vendor de-duplication rules to Hassan Ali | E15: Noura Al Hashimi | F15: 46301 | G15: Closed | H15: 46300 | I15: Rules covering 14% duplicates sent. | J15: =IF(AND(G15<>"Closed",F15<AsOfDate),AsOfDate-F15,"") | K15: =IF(AND(G15<>"Closed",F15<AsOfDate),"Yes","No") -> No
A16: ACT-014 | B16: PMO status | C16: 46303 | D16: Confirm golden vendor records for ZVAE and ZVOM | E16: Hassan Ali | F16: 46310 | G16: Open | I16: Hassan Ali on month-end close; delegate requested. | J16: =IF(AND(G16<>"Closed",F16<AsOfDate),AsOfDate-F16,"") -> 4 | K16: =IF(AND(G16<>"Closed",F16<AsOfDate),"Yes","No") -> Yes
A17: ACT-015 | B17: PMO status | C17: 46303 | D17: Update RAID log owners and last-updated dates before SteerCo | E17: Priya Nair | F17: 46317 | G17: Open | I17: Several items not updated for 3+ weeks. | J17: =IF(AND(G17<>"Closed",F17<AsOfDate),AsOfDate-F17,"") | K17: =IF(AND(G17<>"Closed",F17<AsOfDate),"Yes","No") -> No
A18: ACT-016 | B18: PMO status | C18: 46310 | D18: Prepare SteerCo pack for 28 Oct | E18: Priya Nair | F18: 46321 | G18: In progress | I18: Draft due to Nadia Farouk 26 Oct. | J18: =IF(AND(G18<>"Closed",F18<AsOfDate),AsOfDate-F18,"") | K18: =IF(AND(G18<>"Closed",F18<AsOfDate),"Yes","No") -> No
A19: ACT-017 | B19: PMO status | C19: 46310 | D19: Book ZVQA finance team time for chart of accounts mapping workshop | E19: Hassan Ali | F19: 46311 | G19: Open | I19: Mapping 60% complete. | J19: =IF(AND(G19<>"Closed",F19<AsOfDate),AsOfDate-F19,"") -> 3 | K19: =IF(AND(G19<>"Closed",F19<AsOfDate),"Yes","No") -> Yes
A20: ACT-018 | B20: PMO status | C20: 46310 | D20: Send remediation list for 37 overshared SharePoint sites to site owners | E20: Tom Becker | F20: 46315 | G20: In progress | I20: HR-Payroll and Finance-Board prioritised. | J20: =IF(AND(G20<>"Closed",F20<AsOfDate),AsOfDate-F20,"") | K20: =IF(AND(G20<>"Closed",F20<AsOfDate),"Yes","No") -> No
A21: ACT-019 | B21: Design authority | C21: 46273 | D21: Agree intercompany posting design across ZVAE, ZVSA, ZVOM, ZVQA and ZVHQ | E21: James Okafor | F21: 46287 | G21: Closed | H21: 46287 | I21: Design approved in DA. | J21: =IF(AND(G21<>"Closed",F21<AsOfDate),AsOfDate-F21,"") | K21: =IF(AND(G21<>"Closed",F21<AsOfDate),"Yes","No") -> No
A22: ACT-020 | B22: Design authority | C22: 46280 | D22: Confirm CargoWise integration pattern (API vs file) as fallback | E22: Arjun Mehta | F22: 46294 | G22: Closed | H22: 46294 | I22: API primary, file-based fallback agreed. | J22: =IF(AND(G22<>"Closed",F22<AsOfDate),AsOfDate-F22,"") | K22: =IF(AND(G22<>"Closed",F22<AsOfDate),"Yes","No") -> No
A23: ACT-021 | B23: Design authority | C23: 46287 | D23: Decide whether standard trade agreements replace rate-card engine (CR-009 input) | E23: Rahul Verma | F23: 46301 | G23: Open | I23: Waiting for quote comparison (200 historical quotes). | J23: =IF(AND(G23<>"Closed",F23<AsOfDate),AsOfDate-F23,"") -> 13 | K23: =IF(AND(G23<>"Closed",F23<AsOfDate),"Yes","No") -> Yes
A24: ACT-022 | B24: Design authority | C24: 46294 | D24: Document case routing rules for Arabic and English queues | E24: Lina Mansour | F24: 46301 | G24: Closed | H24: 46301 | I24: Reviewed with Samir Haddad. | J24: =IF(AND(G24<>"Closed",F24<AsOfDate),AsOfDate-F24,"") | K24: =IF(AND(G24<>"Closed",F24<AsOfDate),"Yes","No") -> No
A25: ACT-023 | B25: Design authority | C25: 46301 | D25: Confirm bank file formats for KSA and Oman house banks | E25: James Okafor | F25: 46308 | G25: Open | I25: UAE formats received; KSA and Oman outstanding. | J25: =IF(AND(G25<>"Closed",F25<AsOfDate),AsOfDate-F25,"") -> 6 | K25: =IF(AND(G25<>"Closed",F25<AsOfDate),"Yes","No") -> Yes
A26: ACT-024 | B26: Design authority | C26: 46301 | D26: Review customer portal options for CR-008 (Power Pages vs custom) | E26: Omar Khalil | F26: 46315 | G26: In progress | I26: Power Pages preferred; estimate 45 days. | J26: =IF(AND(G26<>"Closed",F26<AsOfDate),AsOfDate-F26,"") | K26: =IF(AND(G26<>"Closed",F26<AsOfDate),"Yes","No") -> No
A27: ACT-025 | B27: Design authority | C27: 46308 | D27: Agree error handling standard for integrations | E27: Arjun Mehta | F27: 46322 | G27: Open | I27: Draft standard shared. | J27: =IF(AND(G27<>"Closed",F27<AsOfDate),AsOfDate-F27,"") | K27: =IF(AND(G27<>"Closed",F27<AsOfDate),"Yes","No") -> No
A28: ACT-026 | B28: Design authority | C28: 46308 | D28: Validate trade agreement pricing for 200 historical quotes | E28: Lina Mansour | F28: 46318 | G28: In progress | I28: 120 of 200 quotes compared; 6% variance on surcharges. | J28: =IF(AND(G28<>"Closed",F28<AsOfDate),AsOfDate-F28,"") | K28: =IF(AND(G28<>"Closed",F28<AsOfDate),"Yes","No") -> No
A29: ACT-027 | B29: Design authority | C29: 46308 | D29: Confirm sensitivity label taxonomy for Copilot rollout | E29: Tom Becker | F29: 46322 | G29: Open | I29: Elena Petrova to confirm HR labels. | J29: =IF(AND(G29<>"Closed",F29<AsOfDate),AsOfDate-F29,"") | K29: =IF(AND(G29<>"Closed",F29<AsOfDate),"Yes","No") -> No
A30: ACT-028 | B30: Daily stand-up | C30: 46300 | D30: Chase CargoWise vendor for draft API spec v0.9 | E30: Arjun Mehta | F30: 46302 | G30: Closed | H30: 46302 | I30: Draft v0.9 received; final still pending. | J30: =IF(AND(G30<>"Closed",F30<AsOfDate),AsOfDate-F30,"") | K30: =IF(AND(G30<>"Closed",F30<AsOfDate),"Yes","No") -> No
A31: ACT-029 | B31: Daily stand-up | C31: 46302 | D31: Raise ticket for UAT environment storage capacity | E31: Arjun Mehta | F31: 46303 | G31: Closed | H31: 46303 | I31: Resolved. | J31: =IF(AND(G31<>"Closed",F31<AsOfDate),AsOfDate-F31,"") | K31: =IF(AND(G31<>"Closed",F31<AsOfDate),"Yes","No") -> No
A32: ACT-030 | B32: Daily stand-up | C32: 46303 | D32: Pair with WMS developer on wave picking defects | E32: Rahul Verma | F32: 46304 | G32: Closed | H32: 46304 | J32: =IF(AND(G32<>"Closed",F32<AsOfDate),AsOfDate-F32,"") | K32: =IF(AND(G32<>"Closed",F32<AsOfDate),"Yes","No") -> No
A33: ACT-031 | B33: Daily stand-up | C33: 46304 | D33: Send Sprint 3 demo recording to Zava SMEs | E33: Priya Nair | F33: 46307 | G33: Closed | H33: 46307 | J33: =IF(AND(G33<>"Closed",F33<AsOfDate),AsOfDate-F33,"") | K33: =IF(AND(G33<>"Closed",F33<AsOfDate),"Yes","No") -> No
A34: ACT-032 | B34: Daily stand-up | C34: 46307 | D34: Re-plan Sprint 4 integration stories around CargoWise blockers | E34: Arjun Mehta | F34: 46309 | G34: Closed | H34: 46309 | I34: 6 items moved to Blocked. | J34: =IF(AND(G34<>"Closed",F34<AsOfDate),AsOfDate-F34,"") | K34: =IF(AND(G34<>"Closed",F34<AsOfDate),"Yes","No") -> No
A35: ACT-033 | B35: Daily stand-up | C35: 46308 | D35: Fix SLA timer weekend pause bug | E35: Lina Mansour | F35: 46310 | G35: Open | I35: Still Active in Sprint 4. | J35: =IF(AND(G35<>"Closed",F35<AsOfDate),AsOfDate-F35,"") -> 4 | K35: =IF(AND(G35<>"Closed",F35<AsOfDate),"Yes","No") -> Yes
A36: ACT-034 | B36: Daily stand-up | C36: 46308 | D36: Load customer master trial load 1 to Tier 2 | E36: Noura Al Hashimi | F36: 46309 | G36: Closed | H36: 46309 | I36: 98.2% records loaded. | J36: =IF(AND(G36<>"Closed",F36<AsOfDate),AsOfDate-F36,"") | K36: =IF(AND(G36<>"Closed",F36<AsOfDate),"Yes","No") -> No
A37: ACT-035 | B37: Daily stand-up | C37: 46309 | D37: Confirm Arabic character fix for vendor names | E37: Noura Al Hashimi | F37: 46310 | G37: Closed | H37: 46310 | J37: =IF(AND(G37<>"Closed",F37<AsOfDate),AsOfDate-F37,"") | K37: =IF(AND(G37<>"Closed",F37<AsOfDate),"Yes","No") -> No
A38: ACT-036 | B38: Daily stand-up | C38: 46310 | D38: Share KSA bank payment file sample | E38: James Okafor | F38: 46311 | G38: Open | I38: Waiting on bank. | J38: =IF(AND(G38<>"Closed",F38<AsOfDate),AsOfDate-F38,"") -> 3 | K38: =IF(AND(G38<>"Closed",F38<AsOfDate),"Yes","No") -> Yes
A39: ACT-037 | B39: Daily stand-up | C39: 46310 | D39: Update Power BI trial balance dataset for ZVQA | E39: James Okafor | F39: 46316 | G39: In progress | J39: =IF(AND(G39<>"Closed",F39<AsOfDate),AsOfDate-F39,"") | K39: =IF(AND(G39<>"Closed",F39<AsOfDate),"Yes","No") -> No
A40: ACT-038 | B40: Daily stand-up | C40: 46311 | D40: Build CargoWise mock service from draft spec v0.9 | E40: Arjun Mehta | F40: 46317 | G40: In progress | I40: Blocked items can be partly unblocked with mock. | J40: =IF(AND(G40<>"Closed",F40<AsOfDate),AsOfDate-F40,"") | K40: =IF(AND(G40<>"Closed",F40<AsOfDate),"Yes","No") -> No
...

Sheet Summary
A1: ZAV-HZN action summary | Fictitious test data – Copilot for Frontier Consultancy scenario testing
A2: Meeting | B2: Total | C2: Open / in progress | D2: Closed | E2: Overdue
A3: Daily stand-up | B3: =COUNTIFS(Actions!$B$3:$B$42,A3) -> 13 | C3: =COUNTIFS(Actions!$B$3:$B$42,A3,Actions!$G$3:$G$42,"<>Closed") -> 6 | D3: =COUNTIFS(Actions!$B$3:$B$42,A3,Actions!$G$3:$G$42,"Closed") -> 7 | E3: =COUNTIFS(Actions!$B$3:$B$42,A3,Actions!$K$3:$K$42,"Yes") -> 2
A4: Design authority | B4: =COUNTIFS(Actions!$B$3:$B$42,A4) -> 9 | C4: =COUNTIFS(Actions!$B$3:$B$42,A4,Actions!$G$3:$G$42,"<>Closed") -> 6 | D4: =COUNTIFS(Actions!$B$3:$B$42,A4,Actions!$G$3:$G$42,"Closed") -> 3 | E4: =COUNTIFS(Actions!$B$3:$B$42,A4,Actions!$K$3:$K$42,"Yes") -> 2
A5: PMO status | B5: =COUNTIFS(Actions!$B$3:$B$42,A5) -> 10 | C5: =COUNTIFS(Actions!$B$3:$B$42,A5,Actions!$G$3:$G$42,"<>Closed") -> 8 | D5: =COUNTIFS(Actions!$B$3:$B$42,A5,Actions!$G$3:$G$42,"Closed") -> 2 | E5: =COUNTIFS(Actions!$B$3:$B$42,A5,Actions!$K$3:$K$42,"Yes") -> 5
A6: SteerCo | B6: =COUNTIFS(Actions!$B$3:$B$42,A6) -> 8 | C6: =COUNTIFS(Actions!$B$3:$B$42,A6,Actions!$G$3:$G$42,"<>Closed") -> 4 | D6: =COUNTIFS(Actions!$B$3:$B$42,A6,Actions!$G$3:$G$42,"Closed") -> 4 | E6: =COUNTIFS(Actions!$B$3:$B$42,A6,Actions!$K$3:$K$42,"Yes") -> 2
A7: Total | B7: =SUM(B3:B6) -> 40 | C7: =SUM(C3:C6) -> 24 | D7: =SUM(D3:D6) -> 16 | E7: =SUM(E3:E6) -> 11
A9: Owner | B9: Total | C9: Open / in progress | D9: Closed | E9: Overdue
A10: Arjun Mehta | B10: =COUNTIFS(Actions!$E$3:$E$42,A10) -> 6 | C10: =COUNTIFS(Actions!$E$3:$E$42,A10,Actions!$G$3:$G$42,"<>Closed") -> 2 | D10: =COUNTIFS(Actions!$E$3:$E$42,A10,Actions!$G$3:$G$42,"Closed") -> 4 | E10: =COUNTIFS(Actions!$E$3:$E$42,A10,Actions!$K$3:$K$42,"Yes") -> 0
A11: Elena Petrova | B11: =COUNTIFS(Actions!$E$3:$E$42,A11) -> 1 | C11: =COUNTIFS(Actions!$E$3:$E$42,A11,Actions!$G$3:$G$42,"<>Closed") -> 0 | D11: =COUNTIFS(Actions!$E$3:$E$42,A11,Actions!$G$3:$G$42,"Closed") -> 1 | E11: =COUNTIFS(Actions!$E$3:$E$42,A11,Actions!$K$3:$K$42,"Yes") -> 0
A12: Grace Lee | B12: =COUNTIFS(Actions!$E$3:$E$42,A12) -> 1 | C12: =COUNTIFS(Actions!$E$3:$E$42,A12,Actions!$G$3:$G$42,"<>Closed") -> 1 | D12: =COUNTIFS(Actions!$E$3:$E$42,A12,Actions!$G$3:$G$42,"Closed") -> 0 | E12: =COUNTIFS(Actions!$E$3:$E$42,A12,Actions!$K$3:$K$42,"Yes") -> 1
A13: Hassan Ali | B13: =COUNTIFS(Actions!$E$3:$E$42,A13) -> 2 | C13: =COUNTIFS(Actions!$E$3:$E$42,A13,Actions!$G$3:$G$42,"<>Closed") -> 2 | D13: =COUNTIFS(Actions!$E$3:$E$42,A13,Actions!$G$3:$G$42,"Closed") -> 0 | E13: =COUNTIFS(Actions!$E$3:$E$42,A13,Actions!$K$3:$K$42,"Yes") -> 2
A14: James Okafor | B14: =COUNTIFS(Actions!$E$3:$E$42,A14) -> 5 | C14: =COUNTIFS(Actions!$E$3:$E$42,A14,Actions!$G$3:$G$42,"<>Closed") -> 3 | D14: =COUNTIFS(Actions!$E$3:$E$42,A14,Actions!$G$3:$G$42,"Closed") -> 2 | E14: =COUNTIFS(Actions!$E$3:$E$42,A14,Actions!$K$3:$K$42,"Yes") -> 2
A15: Lina Mansour | B15: =COUNTIFS(Actions!$E$3:$E$42,A15) -> 3 | C15: =COUNTIFS(Actions!$E$3:$E$42,A15,Actions!$G$3:$G$42,"<>Closed") -> 2 | D15: =COUNTIFS(Actions!$E$3:$E$42,A15,Actions!$G$3:$G$42,"Closed") -> 1 | E15: =COUNTIFS(Actions!$E$3:$E$42,A15,Actions!$K$3:$K$42,"Yes") -> 1
A16: Nadia Farouk | B16: =COUNTIFS(Actions!$E$3:$E$42,A16) -> 3 | C16: =COUNTIFS(Actions!$E$3:$E$42,A16,Actions!$G$3:$G$42,"<>Closed") -> 1 | D16: =COUNTIFS(Actions!$E$3:$E$42,A16,Actions!$G$3:$G$42,"Closed") -> 2 | E16: =COUNTIFS(Actions!$E$3:$E$42,A16,Actions!$K$3:$K$42,"Yes") -> 1
A17: Noura Al Hashimi | B17: =COUNTIFS(Actions!$E$3:$E$42,A17) -> 3 | C17: =COUNTIFS(Actions!$E$3:$E$42,A17,Actions!$G$3:$G$42,"<>Closed") -> 0 | D17: =COUNTIFS(Actions!$E$3:$E$42,A17,Actions!$G$3:$G$42,"Closed") -> 3 | E17: =COUNTIFS(Actions!$E$3:$E$42,A17,Actions!$K$3:$K$42,"Yes") -> 0
A18: Omar Khalil | B18: =COUNTIFS(Actions!$E$3:$E$42,A18) -> 1 | C18: =COUNTIFS(Actions!$E$3:$E$42,A18,Actions!$G$3:$G$42,"<>Closed") -> 1 | D18: =COUNTIFS(Actions!$E$3:$E$42,A18,Actions!$G$3:$G$42,"Closed") -> 0 | E18: =COUNTIFS(Actions!$E$3:$E$42,A18,Actions!$K$3:$K$42,"Yes") -> 0
A19: Priya Nair | B19: =COUNTIFS(Actions!$E$3:$E$42,A19) -> 7 | C19: =COUNTIFS(Actions!$E$3:$E$42,A19,Actions!$G$3:$G$42,"<>Closed") -> 5 | D19: =COUNTIFS(Actions!$E$3:$E$42,A19,Actions!$G$3:$G$42,"Closed") -> 2 | E19: =COUNTIFS(Actions!$E$3:$E$42,A19,Actions!$K$3:$K$42,"Yes") -> 0
A20: Rahul Verma | B20: =COUNTIFS(Actions!$E$3:$E$42,A20) -> 2 | C20: =COUNTIFS(Actions!$E$3:$E$42,A20,Actions!$G$3:$G$42,"<>Closed") -> 1 | D20: =COUNTIFS(Actions!$E$3:$E$42,A20,Actions!$G$3:$G$42,"Closed") -> 1 | E20: =COUNTIFS(Actions!$E$3:$E$42,A20,Actions!$K$3:$K$42,"Yes") -> 1
A21: Ravi Kumar | B21: =COUNTIFS(Actions!$E$3:$E$42,A21) -> 3 | C21: =COUNTIFS(Actions!$E$3:$E$42,A21,Actions!$G$3:$G$42,"<>Closed") -> 3 | D21: =COUNTIFS(Actions!$E$3:$E$42,A21,Actions!$G$3:$G$42,"Closed") -> 0 | E21: =COUNTIFS(Actions!$E$3:$E$42,A21,Actions!$K$3:$K$42,"Yes") -> 3
A22: Tom Becker | B22: =COUNTIFS(Actions!$E$3:$E$42,A22) -> 3 | C22: =COUNTIFS(Actions!$E$3:$E$42,A22,Actions!$G$3:$G$42,"<>Closed") -> 3 | D22: =COUNTIFS(Actions!$E$3:$E$42,A22,Actions!$G$3:$G$42,"Closed") -> 0 | E22: =COUNTIFS(Actions!$E$3:$E$42,A22,Actions!$K$3:$K$42,"Yes") -> 0
