Workbook
Name AsOfDate: 'Read me'!$B$7

Sheet Read me
A1: Zava M365 Copilot Readiness Data
A2: Fictitious test data – Copilot for Frontier Consultancy scenario testing
A4: Purpose | B4: Microsoft 365 Copilot readiness and pilot data for Zava LLC (600 licences, 120 pilot users), supporting the Change & Copilot Adoption workstream of the Zava Horizon programme. Use for testing adoption reporting, oversharing risk analysis, survey insight extraction and training follow-up scenarios.
A5: Programme | B5: Zava Horizon (ZAV-HZN) – Zava LLC, delivered by Frontier Consulting
A6: Data as of | B6: Monday 19 Oct 2026 (Dubai, UTC+4)
A7: As-of date (used in formulas) | B7: 46314
A8: Currency | B8: AED
A9: Prepared by | B9: Priya Nair, Project Manager (Frontier Consulting) – scenario owner Lorette Roos
A11: Sheet | B11: Contents
A12: Summary | B12: Headline KPIs calculated from the other sheets.
A13: Licences | B13: 600 Copilot licences assigned by department, with pilot and active users.
A14: Usage | B14: Weekly active pilot users (of 120) by app over 8 weeks: Teams, Outlook, Word, Excel, PowerPoint, Copilot Cowork.
A15: SharePoint oversharing | B15: Readiness scan of 60 SharePoint sites: owner, sensitivity label, sharing scope, 'Everyone except external users' (EEEU) and file count. 37 sites flagged.
A16: Pilot survey | B16: 120 pilot survey responses: satisfaction (1–5), minutes saved per week, top use case and free-text comment.
A17: Training completion | B17: Training completion by persona against a 90% target.
A19: Personas | B19: Finance analyst, Customer service agent, Operations supervisor (plus Manager / knowledge worker).
A20: Flag rule | B20: A site is flagged when it is shared with 'Everyone except external users'. No site has a sensitivity label applied.
A22: Important | B22: Fictitious test data – Copilot for Frontier Consultancy scenario testing. All companies, people and figures are fictitious and must not be used for real decisions.

Sheet Summary
A1: Zava M365 Copilot readiness – headline KPIs | Fictitious test data – Copilot for Frontier Consultancy scenario testing
A2: Measure | B2: Value
A3: Copilot licences assigned | B3: =SUM(Licences!C3:C14) -> 600
A4: Pilot users | B4: =SUM(Licences!E3:E14) -> 120
A5: Active users, last 28 days (all licensed) | B5: =SUM(Licences!F3:F14) -> 260
A6: Active rate (licensed users) | B6: =IF(B3=0,0,B5/B3) -> 0.43333333
A7: Weekly active pilot users – latest week | B7: =Usage!H10 -> 108
A8: Weekly active pilot users – first week | B8: =Usage!H3 -> 78
A9: SharePoint sites scanned | B9: =COUNTA('SharePoint oversharing'!A3:A62) -> 60
A10: Sites flagged (EEEU) | B10: =COUNTIFS('SharePoint oversharing'!J3:J62,"Yes") -> 37
A11: Files on flagged sites | B11: =SUMIFS('SharePoint oversharing'!H3:H62,'SharePoint oversharing'!J3:J62,"Yes") -> 152740
A12: Sites with a sensitivity label | B12: =COUNTIFS('SharePoint oversharing'!E3:E62,"<>None") -> 0
A13: Survey responses | B13: =COUNTA('Pilot survey'!A3:A122) -> 120
A14: Average satisfaction (1–5) | B14: =AVERAGE('Pilot survey'!E3:E122) -> 3.8166667
A15: Satisfied (4–5) % | B15: =IF(B13=0,0,COUNTIFS('Pilot survey'!E3:E122,">=4")/B13) -> 0.65833333
A16: Average minutes saved per week | B16: =AVERAGE('Pilot survey'!F3:F122) -> 75.958333
A17: Training completion (all modules) | B17: ='Training completion'!G7 -> 0.52

Sheet Licences
A1: Zava M365 Copilot licences by department | Fictitious test data – Copilot for Frontier Consultancy scenario testing
A2: Department | B2: Headcount | C2: Licences assigned | D2: Licence coverage % | E2: Pilot users | F2: Active users (last 28 days) | G2: Active rate %
A3: Finance | B3: 140 | C3: 95 | D3: =IF(B3=0,0,C3/B3) -> 0.67857143 | E3: 25 | F3: 45 | G3: =IF(C3=0,0,F3/C3) -> 0.47368421
A4: Customer Service | B4: 210 | C4: 110 | D4: =IF(B4=0,0,C4/B4) -> 0.52380952 | E4: 30 | F4: 52 | G4: =IF(C4=0,0,F4/C4) -> 0.47272727
A5: Warehouse Operations | B5: 1150 | C5: 80 | D5: =IF(B5=0,0,C5/B5) -> 0.069565217 | E5: 20 | F5: 37 | G5: =IF(C5=0,0,F5/C5) -> 0.4625
A6: Freight Forwarding | B6: 320 | C6: 75 | D6: =IF(B6=0,0,C6/B6) -> 0.234375 | E6: 12 | F6: 31 | G6: =IF(C6=0,0,F6/C6) -> 0.41333333
A7: Sales & Commercial | B7: 120 | C7: 70 | D7: =IF(B7=0,0,C7/B7) -> 0.58333333 | E7: 10 | F7: 28 | G7: =IF(C7=0,0,F7/C7) -> 0.4
A8: HR | B8: 60 | C8: 35 | D8: =IF(B8=0,0,C8/B8) -> 0.58333333 | E8: 6 | F8: 15 | G8: =IF(C8=0,0,F8/C8) -> 0.42857143
A9: IT | B9: 70 | C9: 45 | D9: =IF(B9=0,0,C9/B9) -> 0.64285714 | E9: 8 | F9: 19 | G9: =IF(C9=0,0,F9/C9) -> 0.42222222
A10: Procurement | B10: 50 | C10: 25 | D10: =IF(B10=0,0,C10/B10) -> 0.5 | E10: 4 | F10: 10 | G10: =IF(C10=0,0,F10/C10) -> 0.4
A11: Legal & Compliance | B11: 25 | C11: 15 | D11: =IF(B11=0,0,C11/B11) -> 0.6 | E11: 2 | F11: 6 | G11: =IF(C11=0,0,F11/C11) -> 0.4
A12: Executive Office | B12: 15 | C12: 15 | D12: =IF(B12=0,0,C12/B12) -> 1 | E12: 3 | F12: 6 | G12: =IF(C12=0,0,F12/C12) -> 0.4
A13: Marketing | B13: 30 | C13: 15 | D13: =IF(B13=0,0,C13/B13) -> 0.5 | E13: 0 | F13: 5 | G13: =IF(C13=0,0,F13/C13) -> 0.33333333
A14: Fleet & Transport | B14: 110 | C14: 20 | D14: =IF(B14=0,0,C14/B14) -> 0.18181818 | E14: 0 | F14: 6 | G14: =IF(C14=0,0,F14/C14) -> 0.3

Sheet Usage
A1: Copilot pilot – weekly active users by app (120 pilot users) | Fictitious test data – Copilot for Frontier Consultancy scenario testing
A2: Week commencing | B2: Teams | C2: Outlook | D2: Word | E2: Excel | F2: PowerPoint | G2: Copilot Cowork | H2: Any Copilot app | I2: Pilot users | J2: Weekly active %
A3: 46258 | B3: 62 | C3: 55 | D3: 30 | E3: 18 | F3: 12 | G3: 48 | H3: 78 | I3: 120 | J3: =IF(I3=0,0,H3/I3) -> 0.65
A4: 46265 | B4: 66 | C4: 61 | D4: 37 | E4: 24 | F4: 13 | G4: 54 | H4: 84 | I4: 120 | J4: =IF(I4=0,0,H4/I4) -> 0.7
A5: 46272 | B5: 76 | C5: 69 | D5: 41 | E5: 26 | F5: 20 | G5: 63 | H5: 89 | I5: 120 | J5: =IF(I5=0,0,H5/I5) -> 0.74166667
A6: 46279 | B6: 80 | C6: 74 | D6: 44 | E6: 28 | F6: 18 | G6: 69 | H6: 93 | I6: 120 | J6: =IF(I6=0,0,H6/I6) -> 0.775
A7: 46286 | B7: 82 | C7: 75 | D7: 47 | E7: 30 | F7: 23 | G7: 70 | H7: 97 | I7: 120 | J7: =IF(I7=0,0,H7/I7) -> 0.80833333
A8: 46293 | B8: 90 | C8: 82 | D8: 50 | E8: 36 | F8: 25 | G8: 78 | H8: 101 | I8: 120 | J8: =IF(I8=0,0,H8/I8) -> 0.84166667
A9: 46300 | B9: 93 | C9: 88 | D9: 56 | E9: 36 | F9: 27 | G9: 81 | H9: 104 | I9: 120 | J9: =IF(I9=0,0,H9/I9) -> 0.86666667
A10: 46307 | B10: 98 | C10: 92 | D10: 58 | E10: 41 | F10: 29 | G10: 88 | H10: 108 | I10: 120 | J10: =IF(I10=0,0,H10/I10) -> 0.9

Sheet SharePoint oversharing
A1: SharePoint oversharing report – Copilot readiness scan | Fictitious test data – Copilot for Frontier Consultancy scenario testing
A2: Site | B2: Site URL | C2: Site owner | D2: Department | E2: Sensitivity label | F2: Sharing scope | G2: Everyone except external users | H2: File count | I2: Last activity | J2: Flagged
A3: HR-Payroll | B3: https://zava.sharepoint.example/sites/HR-Payroll | C3: Elena Petrova | D3: HR | E3: None | F3: Organisation-wide | G3: Yes | H3: 4210 | I3: 46313 | J3: =IF(G3="Yes","Yes","No") -> Yes
A4: Finance-Board | B4: https://zava.sharepoint.example/sites/Finance-Board | C4: Nadia Farouk | D4: Executive | E4: None | F4: Organisation-wide | G4: Yes | H4: 1385 | I4: 46275 | J4: =IF(G4="Yes","Yes","No") -> Yes
A5: HR-Recruitment | B5: https://zava.sharepoint.example/sites/HR-Recruitment | C5: Elena Petrova | D5: HR | E5: None | F5: Organisation-wide | G5: Yes | H5: 2650 | I5: 46300 | J5: =IF(G5="Yes","Yes","No") -> Yes
A6: HR-Policies | B6: https://zava.sharepoint.example/sites/HR-Policies | C6: Elena Petrova | D6: HR | E6: None | F6: Organisation-wide | G6: No | H6: 320 | I6: 46308 | J6: =IF(G6="Yes","Yes","No") -> No
A7: HR-EmployeeRelations | B7: https://zava.sharepoint.example/sites/HR-EmployeeRelations | C7: Elena Petrova | D7: HR | E7: None | F7: Members only | G7: Yes | H7: 890 | I7: 46305 | J7: =IF(G7="Yes","Yes","No") -> Yes
A8: HR-Performance | B8: https://zava.sharepoint.example/sites/HR-Performance | C8: Elena Petrova | D8: HR | E8: None | F8: Organisation-wide | G8: Yes | H8: 1740 | I8: 46262 | J8: =IF(G8="Yes","Yes","No") -> Yes
A9: Finance-AP | B9: https://zava.sharepoint.example/sites/Finance-AP | C9: Hassan Ali | D9: Finance | E9: None | F9: Organisation-wide | G9: Yes | H9: 15820 | I9: 46307 | J9: =IF(G9="Yes","Yes","No") -> Yes
A10: Finance-AR | B10: https://zava.sharepoint.example/sites/Finance-AR | C10: Hassan Ali | D10: Finance | E10: None | F10: Organisation-wide | G10: Yes | H10: 12460 | I10: 46280 | J10: =IF(G10="Yes","Yes","No") -> Yes
A11: Finance-Treasury | B11: https://zava.sharepoint.example/sites/Finance-Treasury | C11: Hassan Ali | D11: Finance | E11: None | F11: Members only | G11: Yes | H11: 3105 | I11: 46298 | J11: =IF(G11="Yes","Yes","No") -> Yes
A12: Finance-Tax-VAT | B12: https://zava.sharepoint.example/sites/Finance-Tax-VAT | C12: Hassan Ali | D12: Finance | E12: None | F12: Organisation-wide | G12: Yes | H12: 2290 | I12: 46309 | J12: =IF(G12="Yes","Yes","No") -> Yes
A13: Finance-ZATCA-KSA | B13: https://zava.sharepoint.example/sites/Finance-ZATCA-KSA | C13: Hassan Ali | D13: Finance | E13: None | F13: Specific people | G13: No | H13: 410 | I13: 46313 | J13: =IF(G13="Yes","Yes","No") -> No
A14: Finance-MonthEnd | B14: https://zava.sharepoint.example/sites/Finance-MonthEnd | C14: Hassan Ali | D14: Finance | E14: None | F14: Organisation-wide | G14: Yes | H14: 8930 | I14: 46312 | J14: =IF(G14="Yes","Yes","No") -> Yes
... A62: Team-Social | B62: https://zava.sharepoint.example/sites/Team-Social | C62: Elena Petrova | D62: HR | E62: None | F62: Organisation-wide | G62: No | H62: 690 | I62: 46313 | J62: =IF(G62="Yes","Yes","No") -> No

Sheet Pilot survey
A1: Copilot pilot survey responses (n = 120) | Fictitious test data – Copilot for Frontier Consultancy scenario testing
A2: Response ID | B2: Submitted | C2: Persona | D2: Department | E2: Satisfaction (1–5) | F2: Minutes saved per week | G2: Top use case | H2: Comment
A3: SRV-001 | B3: 46307 | C3: Finance analyst | D3: Finance | E3: 5 | F3: 120 | G3: Meeting recap in Teams | H3: Helped me prepare for the SteerCo pre-meeting in half the time.
A4: SRV-002 | B4: 46304 | C4: Manager / knowledge worker | D4: IT | E4: 3 | F4: 30 | G4: Meeting recap in Teams | H4: Only works well when files are in OneDrive/SharePoint, not on my desktop.
A5: SRV-003 | B5: 46306 | C5: Operations supervisor | D5: Warehouse Operations | E5: 5 | F5: 120 | G5: Meeting recap in Teams | H5: Very useful for first drafts of SOPs.
A6: SRV-004 | B6: 46305 | C6: Customer service agent | D6: Customer Service | E6: 5 | F6: 155 | G6: Summarise case history | H6: I use it every day in Outlook now.
A7: SRV-005 | B7: 46309 | C7: Manager / knowledge worker | D7: Executive Office | E7: 3 | F7: 40 | G7: Summarise email threads | H7: Works well in Teams; less useful in Excel with our big files.
A8: SRV-006 | B8: 46301 | C8: Customer service agent | D8: Customer Service | E8: 4 | F8: 60 | G8: Meeting recap in Teams | H8: Summarising case history before a call saves me minutes every time.
A9: SRV-007 | B9: 46305 | C9: Manager / knowledge worker | D9: Sales & Commercial | E9: 2 | F9: 10 | G9: Create PowerPoint from Word
A10: SRV-008 | B10: 46305 | C10: Customer service agent | D10: Customer Service | E10: 2 | F10: 80 | G10: Meeting recap in Teams | H10: Copilot surfaced a payroll spreadsheet from the HR site that I should not have access to.
A11: SRV-009 | B11: 46301 | C11: Customer service agent | D11: Customer Service | E11: 4 | F11: 110 | G11: Draft customer replies in Outlook | H11: Great for catching up on long Teams chats with the Jebel Ali team.
A12: SRV-010 | B12: 46306 | C12: Operations supervisor | D12: Warehouse Operations | E12: 4 | F12: 90 | G12: Shift handover summaries | H12: Great for catching up on long Teams chats with the Jebel Ali team.
A13: SRV-011 | B13: 46308 | C13: Customer service agent | D13: Customer Service | E13: 2 | F13: 20 | G13: Meeting recap in Teams
A14: SRV-012 | B14: 46300 | C14: Finance analyst | D14: Finance | E14: 4 | F14: 90 | G14: Meeting recap in Teams | H14: Helped me prepare for the SteerCo pre-meeting in half the time.
A15: SRV-013 | B15: 46305 | C15: Manager / knowledge worker | D15: HR | E15: 4 | F15: 80 | G15: Summarise email threads | H15: The email summaries are excellent when I come back from leave.
A16: SRV-014 | B16: 46300 | C16: Manager / knowledge worker | D16: IT | E16: 4 | F16: 95 | G16: Search across files with Copilot Cowork | H16: Turning Word documents into slides is a big win.
A17: SRV-015 | B17: 46304 | C17: Operations supervisor | D17: Warehouse Operations | E17: 5 | F17: 115 | G17: Draft SOPs in Word | H17: Shift handover summary takes 5 minutes instead of 20.
A18: SRV-016 | B18: 46305 | C18: Finance analyst | D18: Finance | E18: 4 | F18: 90 | G18: Summarise email threads | H18: Helped me prepare for the SteerCo pre-meeting in half the time.
A19: SRV-017 | B19: 46300 | C19: Manager / knowledge worker | D19: IT | E19: 4 | F19: 75 | G19: Create PowerPoint from Word | H19: The email summaries are excellent when I come back from leave.
A20: SRV-018 | B20: 46300 | C20: Operations supervisor | D20: Warehouse Operations | E20: 4 | F20: 70 | G20: Draft SOPs in Word | H20: Great for catching up on long Teams chats with the Jebel Ali team.
A21: SRV-019 | B21: 46303 | C21: Customer service agent | D21: Customer Service | E21: 4 | F21: 70 | G21: Summarise case history | H21: Replying to customers in Arabic and English is much faster.
A22: SRV-020 | B22: 46308 | C22: Operations supervisor | D22: Warehouse Operations | E22: 3 | F22: 55 | G22: Draft SOPs in Word
A23: SRV-021 | B23: 46308 | C23: Manager / knowledge worker | D23: Sales & Commercial | E23: 5 | F23: 120 | G23: Search across files with Copilot Cowork
A24: SRV-022 | B24: 46309 | C24: Customer service agent | D24: Customer Service | E24: 4 | F24: 65 | G24: Draft customer replies in Outlook | H24: I use it every day in Outlook now.
A25: SRV-023 | B25: 46304 | C25: Manager / knowledge worker | D25: HR | E25: 5 | F25: 95 | G25: Summarise email threads | H25: Helped me prepare for the SteerCo pre-meeting in half the time.
A26: SRV-024 | B26: 46300 | C26: Manager / knowledge worker | D26: Legal & Compliance | E26: 4 | F26: 70 | G26: Meeting recap in Teams | H26: Turning Word documents into slides is a big win.
A27: SRV-025 | B27: 46302 | C27: Operations supervisor | D27: Warehouse Operations | E27: 4 | F27: 80 | G27: Draft SOPs in Word | H27: Very useful for first drafts of SOPs.
A28: SRV-026 | B28: 46308 | C28: Finance analyst | D28: Finance | E28: 5 | F28: 125 | G28: Reconciliation analysis in Excel | H28: Month-end variance commentary drafts are 80% there; I just edit.
A29: SRV-027 | B29: 46307 | C29: Manager / knowledge worker | D29: Procurement | E29: 4 | F29: 80 | G29: Summarise email threads | H29: Helped me prepare for the SteerCo pre-meeting in half the time.
A30: SRV-028 | B30: 46307 | C30: Operations supervisor | D30: Warehouse Operations | E30: 3 | F30: 55 | G30: Shift handover summaries | H30: Works well in Teams; less useful in Excel with our big files.
A31: SRV-029 | B31: 46302 | C31: Operations supervisor | D31: Warehouse Operations | E31: 5 | F31: 130 | G31: Shift handover summaries | H31: Saves me a lot of time on meeting notes – I no longer take minutes.
A32: SRV-030 | B32: 46302 | C32: Finance analyst | D32: Finance | E32: 3 | F32: 15 | G32: Month-end commentary in Excel | H32: Good for summaries; drafts still need heavy editing.
A33: SRV-031 | B33: 46304 | C33: Operations supervisor | D33: Warehouse Operations | E33: 5 | F33: 130 | G33: Shift handover summaries | H33: Shift handover summary takes 5 minutes instead of 20.
A34: SRV-032 | B34: 46302 | C34: Operations supervisor | D34: Warehouse Operations | E34: 5 | F34: 120 | G34: Shift handover summaries | H34: Saves me a lot of time on meeting notes – I no longer take minutes.
A35: SRV-033 | B35: 46309 | C35: Operations supervisor | D35: Warehouse Operations | E35: 2 | F35: 15 | G35: Meeting recap in Teams | H35: Copilot surfaced a payroll spreadsheet from the HR site that I should not have access to.
... A50: SRV-048 | B50: 46308 | C50: Customer service agent | D50: Customer Service | E50: 5 | F50: 110 | G50: Meeting recap in Teams | H50: Replying to customers in Arabic and English is much faster.
A51: SRV-049 | B51: 46304 | C51: Manager / knowledge worker | D51: HR | E51: 3 | F51: 60 | G51: Search across files with Copilot Cowork
A52: SRV-050 | B52: 46305 | C52: Operations supervisor | D52: Warehouse Operations | E52: 4 | F52: 75 | G52: Draft SOPs in Word | H52: Saves me a lot of time on meeting notes – I no longer take minutes.
A53: SRV-051 | B53: 46308 | C53: Operations supervisor | D53: Freight Forwarding | E53: 4 | F53: 65 | G53: Meeting recap in Teams | H53: Shift handover summary takes 5 minutes instead of 20.
A54: SRV-052 | B54: 46306 | C54: Manager / knowledge worker | D54: Procurement | E54: 4 | F54: 45 | G54: Create PowerPoint from Word | H54: Saves me a lot of time on meeting notes – I no longer take minutes.
...

Sheet Training completion
A1: Copilot training completion by persona | Fictitious test data – Copilot for Frontier Consultancy scenario testing
A2: Persona | B2: Users in scope | C2: Module 1 – Copilot fundamentals | D2: Module 2 – Prompting for your role | E2: Module 3 – Data protection & responsible use | F2: All modules completed | G2: Completion % (all modules) | H2: Gap to 90% target (users)
A3: Finance analyst | B3: 95 | C3: 91 | D3: 84 | E3: 77 | F3: 72 | G3: =IF(B3=0,0,F3/B3) -> 0.75789474 | H3: =MAX(0,ROUNDUP(B3*$B$10-F3,0)) -> 14
A4: Customer service agent | B4: 110 | C4: 104 | D4: 88 | E4: 79 | F4: 74 | G4: =IF(B4=0,0,F4/B4) -> 0.67272727 | H4: =MAX(0,ROUNDUP(B4*$B$10-F4,0)) -> 25
A5: Operations supervisor | B5: 175 | C5: 139 | D5: 101 | E5: 83 | F5: 70 | G5: =IF(B5=0,0,F5/B5) -> 0.4 | H5: =MAX(0,ROUNDUP(B5*$B$10-F5,0)) -> 88
A6: Manager / knowledge worker | B6: 220 | C6: 176 | D6: 123 | E6: 118 | F6: 96 | G6: =IF(B6=0,0,F6/B6) -> 0.43636364 | H6: =MAX(0,ROUNDUP(B6*$B$10-F6,0)) -> 102
A7: Total | B7: =SUM(B3:B6) -> 600 | C7: =SUM(C3:C6) -> 510 | D7: =SUM(D3:D6) -> 396 | E7: =SUM(E3:E6) -> 357 | F7: =SUM(F3:F6) -> 312 | G7: =IF(B7=0,0,F7/B7) -> 0.52 | H7: =SUM(H3:H6) -> 229
A10: Completion target | B10: 0.9
